<?xml version="1.0" encoding="utf-8"?>
<!-- This URDF was automatically created by SolidWorks to URDF Exporter! Originally created by Stephen Brawner (brawner@gmail.com) 
     Commit Version: 1.6.0-4-g7f85cfe  Build Version: 1.6.7995.38578
     For more information, please see http://wiki.ros.org/sw_urdf_exporter -->
<robot
  name="volcaniarm">
  <link
    name="base_link">
    <inertial>
      <origin
        xyz="0.0033183 1.7612E-06 -0.24794"
        rpy="0 0 0" />
      <mass
        value="5.4796" />
      <inertia
        ixx="0.36605"
        ixy="-2.0049E-09"
        ixz="1.5542E-08"
        iyy="0.19294"
        iyz="-3.1213E-09"
        izz="0.31414" />
    </inertial>
    <visual>
      <origin
        xyz="0 0 0"
        rpy="0 0 0" />
      <geometry>
        <mesh
          filename="/home/tamir/projects/volcaniarm_isaaclab/assets/urdf/meshes/base_link.STL" />
      </geometry>
      <material
        name="">
        <color
          rgba="1 0 0 1" />
      </material>
    </visual>
    <collision>
      <origin
        xyz="0 0 0"
        rpy="0 0 0" />
      <geometry>
        <mesh
          filename="/home/tamir/projects/volcaniarm_isaaclab/assets/urdf/meshes/base_link.STL" />
      </geometry>
    </collision>
  </link>
  <link
    name="fl_table_leg_link">
    <inertial>
      <origin
        xyz="-8.8818E-16 2.2204E-16 0.22347"
        rpy="0 0 0" />
      <mass
        value="0.15157" />
      <inertia
        ixx="0.0028107"
        ixy="-1.2289E-19"
        ixz="2.4795E-22"
        iyy="0.0028135"
        iyz="-2.1305E-20"
        izz="5.0184E-05" />
    </inertial>
    <visual>
      <origin
        xyz="0 0 0"
        rpy="0 0 0" />
      <geometry>
        <mesh
          filename="/home/tamir/projects/volcaniarm_isaaclab/assets/urdf/meshes/fl_table_leg_link.STL" />
      </geometry>
      <material
        name="">
        <color
          rgba="0.79216 0.81961 0.93333 1" />
      </material>
    </visual>
    <collision>
      <origin
        xyz="0 0 0"
        rpy="0 0 0" />
      <geometry>
        <mesh
          filename="/home/tamir/projects/volcaniarm_isaaclab/assets/urdf/meshes/fl_table_leg_link.STL" />
      </geometry>
    </collision>
  </link>
  <joint
    name="fl_table_leg_joint"
    type="fixed">
    <origin
      xyz="0.340000000000002 0.697999999999994 -0.883"
      rpy="0 0 0" />
    <parent
      link="base_link" />
    <child
      link="fl_table_leg_link" />
    <axis
      xyz="0 0 0" />
  </joint>
  <link
    name="fl_caster_wheel_mount_link">
    <inertial>
      <origin
        xyz="-0.011459 -7.0567E-09 -0.011665"
        rpy="0 0 0" />
      <mass
        value="0.047319" />
      <inertia
        ixx="1.6675E-05"
        ixy="-8.0944E-11"
        ixz="-8.1003E-07"
        iyy="2.9049E-05"
        iyz="-7.8988E-11"
        izz="3.76E-05" />
    </inertial>
    <visual>
      <origin
        xyz="0 0 0"
        rpy="0 0 0" />
      <geometry>
        <mesh
          filename="/home/tamir/projects/volcaniarm_isaaclab/assets/urdf/meshes/fl_caster_wheel_mount_link.STL" />
      </geometry>
      <material
        name="">
        <color
          rgba="0.79216 0.81961 0.93333 1" />
      </material>
    </visual>
    <collision>
      <origin
        xyz="0 0 0"
        rpy="0 0 0" />
      <geometry>
        <mesh
          filename="/home/tamir/projects/volcaniarm_isaaclab/assets/urdf/meshes/fl_caster_wheel_mount_link.STL" />
      </geometry>
    </collision>
  </link>
  <joint
    name="fl_caster_wheel_mount_joint"
    type="fixed">
    <origin
      xyz="0 0 0"
      rpy="0 0 0" />
    <parent
      link="fl_table_leg_link" />
    <child
      link="fl_caster_wheel_mount_link" />
    <axis
      xyz="0 0 0" />
  </joint>
  <link
    name="fl_caster_wheel_link">
    <inertial>
      <origin
        xyz="-4.4409E-16 -5.3545E-05 2.2204E-16"
        rpy="0 0 0" />
      <mass
        value="0.12084" />
      <inertia
        ixx="4.6943E-05"
        ixy="2.818E-17"
        ixz="-1.6458E-15"
        iyy="7.6353E-05"
        iyz="4.9306E-17"
        izz="4.6943E-05" />
    </inertial>
    <visual>
      <origin
        xyz="0 0 0"
        rpy="0 0 0" />
      <geometry>
        <mesh
          filename="/home/tamir/projects/volcaniarm_isaaclab/assets/urdf/meshes/fl_caster_wheel_link.STL" />
      </geometry>
      <material
        name="">
        <color
          rgba="0.79216 0.81961 0.93333 1" />
      </material>
    </visual>
    <collision>
      <origin
        xyz="0 0 0"
        rpy="0 0 0" />
      <geometry>
        <mesh
          filename="/home/tamir/projects/volcaniarm_isaaclab/assets/urdf/meshes/fl_caster_wheel_link.STL" />
      </geometry>
    </collision>
  </link>
  <joint
    name="fl_caster_wheel_joint"
    type="fixed">
    <origin
      xyz="-0.0324999999999998 0 -0.0595000000000001"
      rpy="0 0 0" />
    <parent
      link="fl_caster_wheel_mount_link" />
    <child
      link="fl_caster_wheel_link" />
    <axis
      xyz="0 0 0" />
  </joint>
  <link
    name="fr_table_leg_link">
    <inertial>
      <origin
        xyz="-4.4409E-16 -5.5511E-17 0.22347"
        rpy="0 0 0" />
      <mass
        value="0.15157" />
      <inertia
        ixx="0.0028107"
        ixy="-2.7275E-19"
        ixz="3.0345E-21"
        iyy="0.0028135"
        iyz="-2.0783E-19"
        izz="5.0184E-05" />
    </inertial>
    <visual>
      <origin
        xyz="0 0 0"
        rpy="0 0 0" />
      <geometry>
        <mesh
          filename="/home/tamir/projects/volcaniarm_isaaclab/assets/urdf/meshes/fr_table_leg_link.STL" />
      </geometry>
      <material
        name="">
        <color
          rgba="0.79216 0.81961 0.93333 1" />
      </material>
    </visual>
    <collision>
      <origin
        xyz="0 0 0"
        rpy="0 0 0" />
      <geometry>
        <mesh
          filename="/home/tamir/projects/volcaniarm_isaaclab/assets/urdf/meshes/fr_table_leg_link.STL" />
      </geometry>
    </collision>
  </link>
  <joint
    name="fr_table_leg_joint"
    type="fixed">
    <origin
      xyz="0.340000000000005 -0.697999999999998 -0.883"
      rpy="0 0 0" />
    <parent
      link="base_link" />
    <child
      link="fr_table_leg_link" />
    <axis
      xyz="0 0 0" />
  </joint>
  <link
    name="fr_caster_wheel_mount_link">
    <inertial>
      <origin
        xyz="-0.011459 -7.0567E-09 -0.011665"
        rpy="0 0 0" />
      <mass
        value="0.047319" />
      <inertia
        ixx="1.6675E-05"
        ixy="-8.0944E-11"
        ixz="-8.1003E-07"
        iyy="2.9049E-05"
        iyz="-7.8988E-11"
        izz="3.76E-05" />
    </inertial>
    <visual>
      <origin
        xyz="0 0 0"
        rpy="0 0 0" />
      <geometry>
        <mesh
          filename="/home/tamir/projects/volcaniarm_isaaclab/assets/urdf/meshes/fr_caster_wheel_mount_link.STL" />
      </geometry>
      <material
        name="">
        <color
          rgba="0.79216 0.81961 0.93333 1" />
      </material>
    </visual>
    <collision>
      <origin
        xyz="0 0 0"
        rpy="0 0 0" />
      <geometry>
        <mesh
          filename="/home/tamir/projects/volcaniarm_isaaclab/assets/urdf/meshes/fr_caster_wheel_mount_link.STL" />
      </geometry>
    </collision>
  </link>
  <joint
    name="fr_caster_wheel_mount_joint"
    type="fixed">
    <origin
      xyz="0 0 0"
      rpy="0 0 0" />
    <parent
      link="fr_table_leg_link" />
    <child
      link="fr_caster_wheel_mount_link" />
    <axis
      xyz="0 0 0" />
  </joint>
  <link
    name="fr_caster_wheel_link">
    <inertial>
      <origin
        xyz="4.4409E-16 -5.3545E-05 0"
        rpy="0 0 0" />
      <mass
        value="0.12084" />
      <inertia
        ixx="4.6943E-05"
        ixy="2.8346E-17"
        ixz="-1.6458E-15"
        iyy="7.6353E-05"
        iyz="4.9175E-17"
        izz="4.6943E-05" />
    </inertial>
    <visual>
      <origin
        xyz="0 0 0"
        rpy="0 0 0" />
      <geometry>
        <mesh
          filename="/home/tamir/projects/volcaniarm_isaaclab/assets/urdf/meshes/fr_caster_wheel_link.STL" />
      </geometry>
      <material
        name="">
        <color
          rgba="0.79216 0.81961 0.93333 1" />
      </material>
    </visual>
    <collision>
      <origin
        xyz="0 0 0"
        rpy="0 0 0" />
      <geometry>
        <mesh
          filename="/home/tamir/projects/volcaniarm_isaaclab/assets/urdf/meshes/fr_caster_wheel_link.STL" />
      </geometry>
    </collision>
  </link>
  <joint
    name="fr_caster_wheel_joint"
    type="fixed">
    <origin
      xyz="-0.0324999999999998 0 -0.0594999999999999"
      rpy="0 0 0" />
    <parent
      link="fr_caster_wheel_mount_link" />
    <child
      link="fr_caster_wheel_link" />
    <axis
      xyz="0 0 0" />
  </joint>
  <link
    name="rl_table_leg_link">
    <inertial>
      <origin
        xyz="2.2204E-16 4.4409E-16 0.22347"
        rpy="0 0 0" />
      <mass
        value="0.15157" />
      <inertia
        ixx="0.0028107"
        ixy="-3.2292E-21"
        ixz="2.9898E-19"
        iyy="0.0028135"
        iyz="-1.4409E-18"
        izz="5.0184E-05" />
    </inertial>
    <visual>
      <origin
        xyz="0 0 0"
        rpy="0 0 0" />
      <geometry>
        <mesh
          filename="/home/tamir/projects/volcaniarm_isaaclab/assets/urdf/meshes/rl_table_leg_link.STL" />
      </geometry>
      <material
        name="">
        <color
          rgba="0.79216 0.81961 0.93333 1" />
      </material>
    </visual>
    <collision>
      <origin
        xyz="0 0 0"
        rpy="0 0 0" />
      <geometry>
        <mesh
          filename="/home/tamir/projects/volcaniarm_isaaclab/assets/urdf/meshes/rl_table_leg_link.STL" />
      </geometry>
    </collision>
  </link>
  <joint
    name="rl_table_leg_joint"
    type="fixed">
    <origin
      xyz="-0.340000000000005 0.697999999999997 -0.883"
      rpy="0 0 0" />
    <parent
      link="base_link" />
    <child
      link="rl_table_leg_link" />
    <axis
      xyz="0 0 0" />
  </joint>
  <link
    name="rl_caster_wheel_mount_link">
    <inertial>
      <origin
        xyz="-0.011459 -7.0567E-09 -0.011665"
        rpy="0 0 0" />
      <mass
        value="0.047319" />
      <inertia
        ixx="1.6675E-05"
        ixy="-8.0944E-11"
        ixz="-8.1003E-07"
        iyy="2.9049E-05"
        iyz="-7.8988E-11"
        izz="3.76E-05" />
    </inertial>
    <visual>
      <origin
        xyz="0 0 0"
        rpy="0 0 0" />
      <geometry>
        <mesh
          filename="/home/tamir/projects/volcaniarm_isaaclab/assets/urdf/meshes/rl_caster_wheel_mount_link.STL" />
      </geometry>
      <material
        name="">
        <color
          rgba="0.79216 0.81961 0.93333 1" />
      </material>
    </visual>
    <collision>
      <origin
        xyz="0 0 0"
        rpy="0 0 0" />
      <geometry>
        <mesh
          filename="/home/tamir/projects/volcaniarm_isaaclab/assets/urdf/meshes/rl_caster_wheel_mount_link.STL" />
      </geometry>
    </collision>
  </link>
  <joint
    name="rl_caster_wheel_mount_joint"
    type="fixed">
    <origin
      xyz="0 0 0"
      rpy="0 0 0" />
    <parent
      link="rl_table_leg_link" />
    <child
      link="rl_caster_wheel_mount_link" />
    <axis
      xyz="0 0 0" />
  </joint>
  <link
    name="rl_caster_wheel_link">
    <inertial>
      <origin
        xyz="-4.4409E-16 -5.3545E-05 0"
        rpy="0 0 0" />
      <mass
        value="0.12084" />
      <inertia
        ixx="4.6943E-05"
        ixy="2.8172E-17"
        ixz="-1.6458E-15"
        iyy="7.6353E-05"
        iyz="4.8938E-17"
        izz="4.6943E-05" />
    </inertial>
    <visual>
      <origin
        xyz="0 0 0"
        rpy="0 0 0" />
      <geometry>
        <mesh
          filename="/home/tamir/projects/volcaniarm_isaaclab/assets/urdf/meshes/rl_caster_wheel_link.STL" />
      </geometry>
      <material
        name="">
        <color
          rgba="0.79216 0.81961 0.93333 1" />
      </material>
    </visual>
    <collision>
      <origin
        xyz="0 0 0"
        rpy="0 0 0" />
      <geometry>
        <mesh
          filename="/home/tamir/projects/volcaniarm_isaaclab/assets/urdf/meshes/rl_caster_wheel_link.STL" />
      </geometry>
    </collision>
  </link>
  <joint
    name="rl_caster_wheel_joint"
    type="fixed">
    <origin
      xyz="-0.0325 0 -0.0595"
      rpy="0 0 0" />
    <parent
      link="rl_caster_wheel_mount_link" />
    <child
      link="rl_caster_wheel_link" />
    <axis
      xyz="0 0 0" />
  </joint>
  <link
    name="rr_table_leg_link">
    <inertial>
      <origin
        xyz="2.2204E-16 5.5511E-17 0.22347"
        rpy="0 0 0" />
      <mass
        value="0.15157" />
      <inertia
        ixx="0.0028107"
        ixy="-1.4634E-20"
        ixz="3.0914E-21"
        iyy="0.0028135"
        iyz="-2.3759E-18"
        izz="5.0184E-05" />
    </inertial>
    <visual>
      <origin
        xyz="0 0 0"
        rpy="0 0 0" />
      <geometry>
        <mesh
          filename="/home/tamir/projects/volcaniarm_isaaclab/assets/urdf/meshes/rr_table_leg_link.STL" />
      </geometry>
      <material
        name="">
        <color
          rgba="0.79216 0.81961 0.93333 1" />
      </material>
    </visual>
    <collision>
      <origin
        xyz="0 0 0"
        rpy="0 0 0" />
      <geometry>
        <mesh
          filename="/home/tamir/projects/volcaniarm_isaaclab/assets/urdf/meshes/rr_table_leg_link.STL" />
      </geometry>
    </collision>
  </link>
  <joint
    name="rr_table_leg_joint"
    type="fixed">
    <origin
      xyz="-0.339999999999995 -0.698000000000003 -0.883"
      rpy="0 0 0" />
    <parent
      link="base_link" />
    <child
      link="rr_table_leg_link" />
    <axis
      xyz="0 0 0" />
  </joint>
  <link
    name="rr_caster_wheel_mount_link">
    <inertial>
      <origin
        xyz="-0.011459 -7.0567E-09 -0.011665"
        rpy="0 0 0" />
      <mass
        value="0.047319" />
      <inertia
        ixx="1.6675E-05"
        ixy="-8.0944E-11"
        ixz="-8.1003E-07"
        iyy="2.9049E-05"
        iyz="-7.8988E-11"
        izz="3.76E-05" />
    </inertial>
    <visual>
      <origin
        xyz="0 0 0"
        rpy="0 0 0" />
      <geometry>
        <mesh
          filename="/home/tamir/projects/volcaniarm_isaaclab/assets/urdf/meshes/rr_caster_wheel_mount_link.STL" />
      </geometry>
      <material
        name="">
        <color
          rgba="0.79216 0.81961 0.93333 1" />
      </material>
    </visual>
    <collision>
      <origin
        xyz="0 0 0"
        rpy="0 0 0" />
      <geometry>
        <mesh
          filename="/home/tamir/projects/volcaniarm_isaaclab/assets/urdf/meshes/rr_caster_wheel_mount_link.STL" />
      </geometry>
    </collision>
  </link>
  <joint
    name="rr_caster_wheel_mount_joint"
    type="fixed">
    <origin
      xyz="0 0 0"
      rpy="0 0 0" />
    <parent
      link="rr_table_leg_link" />
    <child
      link="rr_caster_wheel_mount_link" />
    <axis
      xyz="0 0 0" />
  </joint>
  <link
    name="rr_caster_wheel_link">
    <inertial>
      <origin
        xyz="0 -5.3545E-05 0"
        rpy="0 0 0" />
      <mass
        value="0.12084" />
      <inertia
        ixx="4.6943E-05"
        ixy="2.8252E-17"
        ixz="-1.6459E-15"
        iyy="7.6353E-05"
        iyz="4.9104E-17"
        izz="4.6943E-05" />
    </inertial>
    <visual>
      <origin
        xyz="0 0 0"
        rpy="0 0 0" />
      <geometry>
        <mesh
          filename="/home/tamir/projects/volcaniarm_isaaclab/assets/urdf/meshes/rr_caster_wheel_link.STL" />
      </geometry>
      <material
        name="">
        <color
          rgba="0.79216 0.81961 0.93333 1" />
      </material>
    </visual>
    <collision>
      <origin
        xyz="0 0 0"
        rpy="0 0 0" />
      <geometry>
        <mesh
          filename="/home/tamir/projects/volcaniarm_isaaclab/assets/urdf/meshes/rr_caster_wheel_link.STL" />
      </geometry>
    </collision>
  </link>
  <joint
    name="rr_caster_wheel_joint"
    type="fixed">
    <origin
      xyz="-0.0324999999999998 0 -0.0595"
      rpy="0 0 0" />
    <parent
      link="rr_caster_wheel_mount_link" />
    <child
      link="rr_caster_wheel_link" />
    <axis
      xyz="0 0 0" />
  </joint>
  <link
    name="volcaniarm_base_link">
    <inertial>
      <origin
        xyz="0.056584 -3.9169E-11 0.053171"
        rpy="0 0 0" />
      <mass
        value="5.2358" />
      <inertia
        ixx="0.045054"
        ixy="5.2217E-06"
        ixz="0.00071509"
        iyy="0.014737"
        iyz="3.2243E-10"
        izz="0.053493" />
    </inertial>
    <visual>
      <origin
        xyz="0 0 0"
        rpy="0 0 0" />
      <geometry>
        <mesh
          filename="/home/tamir/projects/volcaniarm_isaaclab/assets/urdf/meshes/volcaniarm_base_link.STL" />
      </geometry>
      <material
        name="">
        <color
          rgba="0.79216 0.81961 0.93333 1" />
      </material>
    </visual>
    <collision>
      <origin
        xyz="0 0 0"
        rpy="0 0 0" />
      <geometry>
        <mesh
          filename="/home/tamir/projects/volcaniarm_isaaclab/assets/urdf/meshes/volcaniarm_base_link.STL" />
      </geometry>
    </collision>
  </link>
  <joint
    name="volcaniarm_base_joint"
    type="fixed">
    <origin
      xyz="-0.218000000000013 0 -0.0199999999999894"
      rpy="3.14159265358979 0 0" />
    <parent
      link="base_link" />
    <child
      link="volcaniarm_base_link" />
    <axis
      xyz="0 0 0" />
  </joint>
  <link
    name="volcaniarm_left_elbow_link">
    <inertial>
      <origin
        xyz="-0.0035388 0.00032928 0.20807"
        rpy="0 0 0" />
      <mass
        value="0.25539" />
      <inertia
        ixx="0.0015999"
        ixy="2.5707E-06"
        ixz="-4.8958E-07"
        iyy="0.0016014"
        iyz="-4.1044E-06"
        izz="8.8962E-05" />
    </inertial>
    <visual>
      <origin
        xyz="0 0 0"
        rpy="0 0 0" />
      <geometry>
        <mesh
          filename="/home/tamir/projects/volcaniarm_isaaclab/assets/urdf/meshes/volcaniarm_left_elbow_link.STL" />
      </geometry>
      <material
        name="">
        <color
          rgba="0.25098 0.25098 0.25098 1" />
      </material>
    </visual>
    <collision>
      <origin
        xyz="0 0 0"
        rpy="0 0 0" />
      <geometry>
        <mesh
          filename="/home/tamir/projects/volcaniarm_isaaclab/assets/urdf/meshes/volcaniarm_left_elbow_link.STL" />
      </geometry>
    </collision>
  </link>
  <joint
    name="volcaniarm_left_elbow_joint"
    type="revolute">
    <origin
      xyz="0.285000000000036 -0.214999999999991 0.0632000000000055"
      rpy="0.785398163397457 0 0" />
    <parent
      link="volcaniarm_base_link" />
    <child
      link="volcaniarm_left_elbow_link" />
    <axis
      xyz="1 0 0" />
    <limit
      lower="-3.14"
      upper="3.14"
      effort="10"
      velocity="10" />
    <dynamics
      damping="0.1"
      friction="0.1" />
  </joint>
  <link
    name="volcaniarm_left_arm_link">
    <inertial>
      <origin
        xyz="2.2204E-16 -0.019365 0.31121"
        rpy="0 0 0" />
      <mass
        value="0.31139" />
      <inertia
        ixx="0.0060642"
        ixy="-1.1232E-13"
        ixz="7.5126E-14"
        iyy="0.0060587"
        iyz="1.0603E-13"
        izz="0.00011844" />
    </inertial>
    <visual>
      <origin
        xyz="0 0 0"
        rpy="0 0 0" />
      <geometry>
        <mesh
          filename="/home/tamir/projects/volcaniarm_isaaclab/assets/urdf/meshes/volcaniarm_left_arm_link.STL" />
      </geometry>
      <material
        name="">
        <color
          rgba="0.79216 0.81961 0.93333 1" />
      </material>
    </visual>
    <collision>
      <origin
        xyz="0 0 0"
        rpy="0 0 0" />
      <geometry>
        <mesh
          filename="/home/tamir/projects/volcaniarm_isaaclab/assets/urdf/meshes/volcaniarm_left_arm_link.STL" />
      </geometry>
    </collision>
  </link>
  <joint
    name="volcaniarm_left_arm_joint"
    type="revolute">
    <origin
      xyz="0.00399999999997247 0.0200000000000011 0.416213203435623"
      rpy="-1.70529629561765 0 0" />
    <parent
      link="volcaniarm_left_elbow_link" />
    <child
      link="volcaniarm_left_arm_link" />
    <axis
      xyz="-1 0 0" />
    <limit
      lower="-3.14"
      upper="3.14"
      effort="10"
      velocity="10" />
    <dynamics
      damping="0.1"
      friction="0.1" />
  </joint>
  <link
    name="left_ee_link">
    <inertial>
      <origin
        xyz="0 0 0"
        rpy="0 0 0" />
      <mass
        value="0.05" />
      <inertia
        ixx="1e-5"
        ixy="0"
        ixz="0"
        iyy="1e-5"
        iyz="0"
        izz="1e-5" />
    </inertial>
  </link>
  <joint
    name="left_ee_joint"
    type="fixed">
    <origin
      xyz="0 0 0.62243"
      rpy="0 0 0" />
    <parent
      link="volcaniarm_left_arm_link" />
    <child
      link="left_ee_link" />
    <axis
      xyz="0 0 0" />
  </joint>
  <link
    name="volcaniarm_right_elbow_link">
    <inertial>
      <origin
        xyz="-0.0035272 -0.0032768 0.20822"
        rpy="0 0 0" />
      <mass
        value="0.25516" />
      <inertia
        ixx="0.0015999"
        ixy="2.5707E-06"
        ixz="-4.8958E-07"
        iyy="0.0016014"
        iyz="2.7775E-06"
        izz="8.8958E-05" />
    </inertial>
    <visual>
      <origin
        xyz="0 0 0"
        rpy="0 0 0" />
      <geometry>
        <mesh
          filename="/home/tamir/projects/volcaniarm_isaaclab/assets/urdf/meshes/volcaniarm_right_elbow_link.STL" />
      </geometry>
      <material
        name="">
        <color
          rgba="0.79216 0.81961 0.93333 1" />
      </material>
    </visual>
    <collision>
      <origin
        xyz="0 0 0"
        rpy="0 0 0" />
      <geometry>
        <mesh
          filename="/home/tamir/projects/volcaniarm_isaaclab/assets/urdf/meshes/volcaniarm_right_elbow_link.STL" />
      </geometry>
    </collision>
  </link>
  <joint
    name="volcaniarm_right_elbow_joint"
    type="revolute">
    <origin
      xyz="0.289000000000013 0.215 0.0632000000000104"
      rpy="-0.785398163397448 0 0" />
    <parent
      link="volcaniarm_base_link" />
    <child
      link="volcaniarm_right_elbow_link" />
    <axis
      xyz="1 0 0" />
    <limit
      lower="-3.14"
      upper="3.14"
      effort="10"
      velocity="10" />
    <dynamics
      damping="0.1"
      friction="0.1" />
  </joint>
  <link
    name="volcaniarm_right_arm_link">
    <inertial>
      <origin
        xyz="-0.00010972 0.018304 0.32828"
        rpy="0 0 0" />
      <mass
        value="0.32945" />
      <inertia
        ixx="0.0060651"
        ixy="4.6871E-12"
        ixz="3.074E-12"
        iyy="0.0060639"
        iyz="3.1157E-09"
        izz="0.00012364" />
    </inertial>
    <visual>
      <origin
        xyz="0 0 0"
        rpy="0 0 0" />
      <geometry>
        <mesh
          filename="/home/tamir/projects/volcaniarm_isaaclab/assets/urdf/meshes/volcaniarm_right_arm_link.STL" />
      </geometry>
      <material
        name="">
        <color
          rgba="0.79216 0.81961 0.93333 1" />
      </material>
    </visual>
    <collision>
      <origin
        xyz="0 0 0"
        rpy="0 0 0" />
      <geometry>
        <mesh
          filename="/home/tamir/projects/volcaniarm_isaaclab/assets/urdf/meshes/volcaniarm_right_arm_link.STL" />
      </geometry>
    </collision>
  </link>
  <joint
    name="volcaniarm_right_arm_joint"
    type="revolute">
    <origin
      xyz="0.004 -0.02 0.41621"
      rpy="1.7053 0 0" />
    <parent
      link="volcaniarm_right_elbow_link" />
    <child
      link="volcaniarm_right_arm_link" />
    <axis
      xyz="1 0 0" />
    <limit
      lower="-3.14"
      upper="3.14"
      effort="10"
      velocity="10" />
    <dynamics
      damping="0.1"
      friction="0.1" />
  </joint>
  <link
    name="right_ee_link">
    <inertial>
      <origin
        xyz="0 0 0"
        rpy="0 0 0" />
      <mass
        value="0.05" />
      <inertia
        ixx="1e-5"
        ixy="0"
        ixz="0"
        iyy="1e-5"
        iyz="0"
        izz="1e-5" />
    </inertial>
  </link>
  <joint
    name="right_ee_joint"
    type="fixed">
    <origin
      xyz="0 0 0.62243"
      rpy="0 0 0" />
    <parent
      link="volcaniarm_right_arm_link" />
    <child
      link="right_ee_link" />
    <axis
      xyz="0 0 0" />
  </joint>
  <link
    name="camera_mount_linear_link">
    <inertial>
      <origin
        xyz="0 0 0"
        rpy="0 0 0" />
      <mass
        value="0" />
      <inertia
        ixx="0"
        ixy="0"
        ixz="0"
        iyy="0"
        iyz="0"
        izz="0" />
    </inertial>
    <visual>
      <origin
        xyz="0 0 0"
        rpy="0 0 0" />
      <geometry>
        <mesh
          filename="/home/tamir/projects/volcaniarm_isaaclab/assets/urdf/meshes/camera_mount_linear_link.STL" />
      </geometry>
      <material
        name="">
        <color
          rgba="1 1 1 1" />
      </material>
    </visual>
    <collision>
      <origin
        xyz="0 0 0"
        rpy="0 0 0" />
      <geometry>
        <mesh
          filename="/home/tamir/projects/volcaniarm_isaaclab/assets/urdf/meshes/camera_mount_linear_link.STL" />
      </geometry>
    </collision>
  </link>
  <joint
    name="camera_mount_linear_joint"
    type="prismatic">
    <origin
      xyz="0.405353761834025 0 0.039999999999992"
      rpy="0 0 0" />
    <parent
      link="base_link" />
    <child
      link="camera_mount_linear_link" />
    <axis
      xyz="1 0 0" />
    <limit
      lower="-0.3"
      upper="0.3"
      effort="10"
      velocity="10" />
    <dynamics
      damping="0.1"
      friction="0.1" />
  </joint>
  <link
    name="camera_mount_rev_link">
    <inertial>
      <origin
        xyz="-0.00010268 -1.5812E-06 0.01215"
        rpy="0 0 0" />
      <mass
        value="0.006837" />
      <inertia
        ixx="2.4745E-06"
        ixy="8.8137E-13"
        ixz="-4.848E-10"
        iyy="2.6062E-07"
        iyz="-1.1636E-11"
        izz="2.5357E-06" />
    </inertial>
    <visual>
      <origin
        xyz="0 0 0"
        rpy="0 0 0" />
      <geometry>
        <mesh
          filename="/home/tamir/projects/volcaniarm_isaaclab/assets/urdf/meshes/camera_mount_rev_link.STL" />
      </geometry>
      <material
        name="">
        <color
          rgba="0.79216 0.81961 0.93333 1" />
      </material>
    </visual>
    <collision>
      <origin
        xyz="0 0 0"
        rpy="0 0 0" />
      <geometry>
        <mesh
          filename="/home/tamir/projects/volcaniarm_isaaclab/assets/urdf/meshes/camera_mount_rev_link.STL" />
      </geometry>
    </collision>
  </link>
  <joint
    name="camera_mount_rev_joint"
    type="revolute">
    <origin
      xyz="0.192000000000008 0 -0.0290000000000052"
      rpy="3.14159265358979 0.211904134210419 3.14159265358979" />
    <parent
      link="camera_mount_linear_link" />
    <child
      link="camera_mount_rev_link" />
    <axis
      xyz="0 1 0" />
    <limit
      lower="-3.14"
      upper="3.14"
      effort="10"
      velocity="10" />
    <dynamics
      damping="0.1"
      friction="0.1" />
  </joint>
  <link
    name="camera_link">
    <inertial>
      <origin
        xyz="-6.0189E-07 0.00024591 0.011952"
        rpy="0 0 0" />
      <mass
        value="0.044753" />
      <inertia
        ixx="2.7362E-05"
        ixy="3.9858E-09"
        ixz="7.9052E-10"
        iyy="3.9447E-06"
        iyz="2.4433E-07"
        izz="2.7278E-05" />
    </inertial>
    <visual>
      <origin
        xyz="0 0 0"
        rpy="0 0 0" />
      <geometry>
        <mesh
          filename="/home/tamir/projects/volcaniarm_isaaclab/assets/urdf/meshes/camera_link.STL" />
      </geometry>
      <material
        name="">
        <color
          rgba="0.79216 0.81961 0.93333 1" />
      </material>
    </visual>
    <collision>
      <origin
        xyz="0 0 0"
        rpy="0 0 0" />
      <geometry>
        <mesh
          filename="/home/tamir/projects/volcaniarm_isaaclab/assets/urdf/meshes/camera_link.STL" />
      </geometry>
    </collision>
  </link>
  <joint
    name="camera_joint"
    type="fixed">
    <origin
      xyz="-2.37779715432929E-05 0 0.0160004150359285"
      rpy="0 -0.0135473024600912 0" />
    <parent
      link="camera_mount_rev_link" />
    <child
      link="camera_link" />
    <axis
      xyz="0 0 0" />
  </joint>
</robot>